<?xml version="1.0" ?>
<!-- =================================================================================== -->
<!-- |    This document was autogenerated by xacro from nao_robot.xacro                | -->
<!-- |    EDITING THIS FILE BY HAND IS NOT RECOMMENDED                                 | -->
<!-- =================================================================================== -->
<!--******************************************************************
 ****** File automatically generated by generate_urdf.py script ******
 *********************************************************************-->
<robot name="Nao" xmlns:xacro="http://www.ros.org/wiki/xacro">
  <!-- Base link -->
  <link name="base">
    <collision>
      <origin rpy="0 0 0" xyz="0 0 0"/>
      <geometry>
        <box size="0.01 0.01 0.01"/>
      </geometry>
    </collision>
    <visual>
      <origin rpy="0 0 0" xyz="0 0 0"/>
      <geometry>
        <box size="0.02 0.06 0.15"/>
      </geometry>
      <material name="green"/>
    </visual>

  </link>
  <joint name="base_to_torso" type="fixed">
    <parent link="base"/>
    <child link="torso"/>
    <origin rpy="0 0 0" xyz="0 0 0"/>
  </joint>
  <!-- Dummy inertia link, because KDL cannot have inertia on the main link -->
  <link name="torso">
    <visual>
      <origin rpy="0 0 0" xyz="0 0 0"/>
      <geometry>
        <mesh filename="../meshes/Torso.dae" scale="0.1 0.1 0.1"/>
      </geometry>
    </visual>
    <!-- Main Body -->
   <inertial>
      <mass value="1.0496"/>
      <inertia ixx="0.00506" ixy="1.43116e-05" ixz="0.000155" iyy="0.00488" iyz="-2.70793e-05" izz="0.00161"/>
      <origin rpy="0 0 0" xyz="-0.00413 0 0.04342"/>
    </inertial>
    <collision>
      <origin rpy="0 0 0" xyz="0 0 0.02"/>
      <geometry>
        <!-- <mesh filename="../meshes/Torso.obj" scale="0.1 0.1 0.1"/> -->
        <cylinder length="0.06" radius="0.07"/>
      </geometry>
    </collision>
  </link>

  <joint name="HeadYaw" type="fixed">
    <parent link="torso"/>
    <child link="Neck"/>
    <origin rpy="0 0 0" xyz="0 0 0.1265"/>
    <axis xyz="0 0 1.0"/>
    <limit effort="1.547" lower="-2.08567" upper="2.08567" velocity="8.26797"/>
  </joint>
  <link name="Neck">
    <inertial>
      <mass value="0.07842"/>
      <inertia ixx="7.499e-05" ixy="1.57e-09" ixz="-1.834e-08" iyy="7.6e-05" iyz="-5.295e-08" izz="5.53372e-06"/>
      <origin rpy="0 0 0" xyz="-1e-05 0 -0.02742"/>
    </inertial>
    <visual>
      <geometry>
        <mesh filename="../meshes/HeadYaw.dae" scale="0.1 0.1 0.1"/>
      </geometry>
      <origin rpy="0 0 0" xyz="0 0 0"/>
    </visual>
    <!-- <collision>
      <geometry>
        <mesh filename="../meshes/HeadYaw.obj" scale="0.1 0.1 0.1"/>
      </geometry>
      <origin rpy="0 0 0" xyz="0 0 0"/>
    </collision> -->
  </link>
  <joint name="HeadPitch" type="fixed">
    <parent link="Neck"/>
    <child link="Head"/>
    <origin rpy="0 0 0" xyz="0 0 0"/>
    <axis xyz="0 1.0 0"/>
    <limit effort="1.532" lower="-0.671952" upper="0.514872" velocity="7.19407"/>
  </joint>
  <link name="Head">
    <inertial>
      <mass value="0.60533"/>
      <inertia ixx="0.00293" ixy="3.717e-06" ixz="-3.1447e-05" iyy="0.0028386" iyz="-7.3773e-05" izz="0.0007169"/>
      <origin rpy="0 0 0" xyz="-0.00112 0 0.05258"/>
    </inertial>
    <visual>
      <geometry>
        <mesh filename="../meshes/HeadPitch.dae" scale="0.1 0.1 0.1"/>
      </geometry>
      <origin rpy="0 0 0" xyz="0 0 0"/>
    </visual>
    <collision>
      <geometry>
        <!-- <mesh filename="../meshes/HeadPitch.obj" scale="0.1 0.08 0.1"/> -->
        <cylinder length="0.02" radius="0.05"/>
      </geometry>
      <origin rpy="1.57 0 0" xyz="0 0 0.07"/>
    </collision>
  </link>
  <joint name="gaze_joint" type="fixed">
    <parent link="Head"/>
    <child link="gaze"/>
    <origin rpy="0 0 0" xyz="0.05871 0 0.06364"/>
  </joint>
  <link name="gaze"/>
  <link name="base_link"/>
  <joint name="base_link_fixedjoint" type="fixed">
    <parent link="base_link"/>
    <child link="torso"/>
    <origin rpy="0 0 0" xyz="0 0 0"/>
    <axis xyz="0 0 0"/>
  </joint>
  <joint name="LShoulderPitch" type="fixed">
    <parent link="torso"/>
    <child link="LShoulder"/>
    <origin rpy="0 1.6 0" xyz="0 0.098 0.1"/>
    <axis xyz="0 1.0 0"/>
    <limit effort="1.329" lower="-2.08567" upper="2.08567" velocity="8.26797"/>
  </joint>
  <link name="LShoulder">
    <inertial>
      <mass value="0.09304"/>
      <inertia ixx="8.428e-05" ixy="-2.028e-06" ixz="2.338e-08" iyy="1.4156e-05" iyz="-1.972e-08" izz="8.642e-05"/>
      <origin rpy="0 0 0" xyz="-0.00165 -0.02663 0.00014"/>
    </inertial>
    <visual>
      <geometry>
        <mesh filename="../meshes/LShoulderPitch.dae" scale="0.1 0.1 0.1"/>
      </geometry>
      <origin rpy="0 0 0" xyz="0 0 0"/>
    </visual>
<!--     <collision>
      <geometry>
        <mesh filename="../meshes/LShoulderPitch.obj" scale="0.1 0.1 0.1"/>
      </geometry>
      <origin rpy="0 0 0" xyz="0 0 0"/>
    </collision> -->
  </link>
  <joint name="LShoulderRoll" type="fixed">
    <parent link="LShoulder"/>
    <child link="LBicep"/>
    <origin rpy="0 0 0.3" xyz="0 0 0"/>
    <axis xyz="0 0 1.0"/>
    <limit effort="1.7835" lower="-0.314159" upper="1.32645" velocity="7.19407"/>
  </joint>
  <link name="LBicep">
    <inertial>
      <mass value="0.15777"/>
      <inertia ixx="9.39e-05" ixy="-4.714e-05" ixz="-2.699e-05" iyy="0.000372" iyz="-2.46e-06" izz="0.000342"/>
      <origin rpy="0 0 0" xyz="0.02455 0.00563 0.0033"/>
    </inertial>
    <visual>
      <geometry>
        <mesh filename="../meshes/LShoulderRoll.dae" scale="0.1 0.1 0.1"/>
      </geometry>
      <origin rpy="0 0 0" xyz="0 0 0"/>
    </visual>
    <!-- <collision>
      <geometry>
        <mesh filename="../meshes/LShoulderRoll.obj" scale="0.1 0.1 0.1"/>
      </geometry>
      <origin rpy="0 0 0" xyz="0 0 0"/>
    </collision> -->
  </link>
  <joint name="LElbowYaw" type="fixed">
    <parent link="LBicep"/>
    <child link="LElbow"/>
    <origin rpy="0 0 0" xyz="0.105 0.015 0"/>
    <axis xyz="1.0 0 0"/>
    <limit effort="1.547" lower="-2.08567" upper="2.08567" velocity="8.26797"/>
  </joint>
  <link name="LElbow">
    <inertial>
      <mass value="0.06483"/>
      <inertia ixx="5.597e-06" ixy="4.21e-09" ixz="4.319e-08" iyy="7.543e-05" iyz="-1.84e-09" izz="7.644e-05"/>
      <origin rpy="0 0 0" xyz="-0.02744 0 -0.00014"/>
    </inertial>
  </link>
  <joint name="LElbowRoll" type="fixed">
    <parent link="LElbow"/>
    <child link="LForeArm"/>
    <origin rpy="0 0 0" xyz="0 0 0"/>
    <axis xyz="0 0 1.0"/>
    <limit effort="1.532" lower="-1.54462" upper="-0.0349066" velocity="7.19407"/>
  </joint>
  <link name="LForeArm">
    <inertial>
      <mass value="0.07761"/>
      <inertia ixx="2.533e-05" ixy="-2.343e-06" ixz="7.459e-08" iyy="8.913e-05" iyz="-2.655e-08" izz="8.729e-05"/>
      <origin rpy="0 0 0" xyz="0.02556 0.00281 0.00076"/>
    </inertial>
    <visual>
      <geometry>
        <mesh filename="../meshes/LElbowRoll.dae" scale="0.1 0.1 0.1"/>
      </geometry>
      <origin rpy="0 0 0" xyz="0 0 0"/>
    </visual>
    <!-- <collision>
      <geometry>
        <mesh filename="../meshes/LElbowRoll.obj" scale="0.1 0.1 0.1"/>
      </geometry>
      <origin rpy="0 0 0" xyz="0 0 0"/>
    </collision> -->
  </link>
  <joint name="LWristYaw" type="fixed">
    <parent link="LForeArm"/>
    <child link="l_wrist"/>
    <origin rpy="0 0 0" xyz="0.05595 0 0"/>
    <axis xyz="1.0 0 0"/>
    <limit effort="0.4075" lower="-1.82387" upper="1.82387" velocity="24.6229"/>
  </joint>
  <link name="l_wrist">
    <inertial>
      <mass value="0.18533"/>
      <inertia ixx="7.055e-05" ixy="5.716e-06" ixz="-2.247e-05" iyy="0.000356" iyz="3.178e-06" izz="0.000352"/>
      <origin rpy="0 0 0" xyz="0.03434 -0.00088 0.00308"/>
    </inertial>
    <visual>
      <geometry>
        <mesh filename="../meshes/LWristYaw.dae" scale="0.1 0.1 0.1"/>
      </geometry>
      <origin rpy="0 0 0" xyz="0 0 0"/>
    </visual>
    <collision>
      <geometry>
        <!-- <mesh filename="../meshes/LWristYaw.obj" scale="0.1 0.1 0.1"/> -->
        <cylinder length="0.08" radius="0.03"/>
      </geometry>
      <origin rpy="0 1.57079 0" xyz="0 0 0"/>
    </collision>
  </link>
  <joint name="LHand" type="fixed">
    <parent link="l_wrist"/>
    <child link="l_gripper"/>
    <origin rpy="0 0 0" xyz="0.05775 0 -0.01231"/>
    <axis xyz="1.0 0 0"/>
    <limit effort="0.292" lower="0" upper="1.0" velocity="8.33"/>
  </joint>
  <link name="l_gripper">
    <inertial>
      <mass value="2e-06"/>
      <inertia ixx="1.1e-09" ixy="0" ixz="0" iyy="1.1e-09" iyz="0" izz="1.1e-09"/>
    </inertial>
  </link>
  <joint name="RShoulderPitch" type="fixed">
    <parent link="torso"/>
    <child link="RShoulder"/>
    <origin rpy="0 1.6 0" xyz="0 -0.098 0.1"/>
    <axis xyz="0 1.0 0"/>
    <limit effort="1.329" lower="-2.08567" upper="2.08567" velocity="8.26797"/>
  </joint>
  <link name="RShoulder">
    <inertial>
      <mass value="0.09304"/>
      <inertia ixx="8.428e-05" ixy="2.028e-06" ixz="2.338e-08" iyy="1.4156e-05" iyz="1.972e-08" izz="8.642e-05"/>
      <origin rpy="0 0 0" xyz="-0.00165 0.02663 0.00014"/>
    </inertial>
    <visual>
      <geometry>
        <mesh filename="../meshes/RShoulderPitch.dae" scale="0.1 0.1 0.1"/>
      </geometry>
      <origin rpy="0 0 0" xyz="0 0 0"/>
    </visual>
<!--     <collision>
      <geometry>
        <mesh filename="../meshes/RShoulderPitch.obj" scale="0.1 0.1 0.1"/>
      </geometry>
      <origin rpy="0 0 0" xyz="0 0 0"/>
    </collision> -->
  </link>
  <joint name="RShoulderRoll" type="fixed">
    <parent link="RShoulder"/>
    <child link="RBicep"/>
    <origin rpy="0 0 -0.3" xyz="0 0 0"/>
    <axis xyz="0 0 1.0"/>
    <limit effort="1.783" lower="-1.32645" upper="0.314159" velocity="7.19407"/>
  </joint>
  <link name="RBicep">
    <inertial>
      <mass value="0.15777"/>
      <inertia ixx="0.00011" ixy="7.669e-05" ixz="-2.604e-05" iyy="0.0003676" iyz="1.21e-05" izz="0.0003546"/>
      <origin rpy="0 0 0" xyz="0.02455 -0.00563 0.0033"/>
    </inertial>
    <visual>
      <geometry>
        <mesh filename="../meshes/RShoulderRoll.dae" scale="0.1 0.1 0.1"/>
      </geometry>
      <origin rpy="0 0 0" xyz="0 0 0"/>
    </visual>
    <!-- <collision>
      <geometry>
        <mesh filename="../meshes/RShoulderRoll.obj" scale="0.1 0.1 0.1"/>
      </geometry>
      <origin rpy="0 0 0" xyz="0 0 0"/>
    </collision> -->
  </link>
  <joint name="RElbowYaw" type="fixed">
    <parent link="RBicep"/>
    <child link="RElbow"/>
    <origin rpy="0 0 0" xyz="0.105 -0.015 0"/>
    <axis xyz="1.0 0 0"/>
    <limit effort="1.547" lower="-2.08567" upper="2.08567" velocity="8.26797"/>
  </joint>
  <link name="RElbow">
    <inertial>
      <mass value="0.06483"/>
      <inertia ixx="5.597e-06" ixy="4.21e-09" ixz="4.319e-08" iyy="7.543e-05" iyz="-1.84e-09" izz="7.644e-05"/>
      <origin rpy="0 0 0" xyz="-0.02744 0 -0.00014"/>
    </inertial>
  </link>
  <joint name="RElbowRoll" type="fixed">
    <parent link="RElbow"/>
    <child link="RForeArm"/>
    <origin rpy="0 0 0" xyz="0 0 0"/>
    <axis xyz="0 0 1.0"/>
    <limit effort="1.532" lower="0.0349066" upper="1.54462" velocity="7.19407"/>
  </joint>
  <link name="RForeArm">
    <inertial>
      <mass value="0.07761"/>
      <inertia ixx="2.539e-05" ixy="2.332e-06" ixz="-6.012e-07" iyy="8.922e-05" iyz="2.694e-08" izz="8.725e-05"/>
      <origin rpy="0 0 0" xyz="0.02556 -0.00281 0.00076"/>
    </inertial>
    <visual>
      <geometry>
        <mesh filename="../meshes/RElbowRoll.dae" scale="0.1 0.1 0.1"/>
      </geometry>
      <origin rpy="0 0 0" xyz="0 0 0"/>
    </visual>
    <!-- <collision>
      <geometry>
        <mesh filename="../meshes/RElbowRoll.obj" scale="0.1 0.1 0.1"/>
      </geometry>
      <origin rpy="0 0 0" xyz="0 0 0"/>
    </collision> -->
  </link>
  <joint name="RWristYaw" type="fixed">
    <parent link="RForeArm"/>
    <child link="r_wrist"/>
    <origin rpy="0 0 0" xyz="0.05595 0 0"/>
    <axis xyz="1.0 0 0"/>
    <limit effort="0.4075" lower="-1.82387" upper="1.82387" velocity="24.6229"/>
  </joint>
  <link name="r_wrist">
    <inertial>
      <mass value="0.18533"/>
      <inertia ixx="7.055e-05" ixy="5.716e-06" ixz="-2.247e-05" iyy="0.000356" iyz="3.178e-06" izz="0.000352"/>
      <origin rpy="0 0 0" xyz="0.03434 0.00088 0.00308"/>
    </inertial>
    <visual>
      <geometry>
        <mesh filename="../meshes/RWristYaw.dae" scale="0.1 0.1 0.1"/>
      </geometry>
      <origin rpy="0 0 0" xyz="0 0 0"/>
    </visual>
    <collision>
      <geometry>
        <!-- <mesh filename="../meshes/RWristYaw.obj" scale="0.1 0.1 0.1"/> -->
        <cylinder length="0.08" radius="0.03"/>
      </geometry>
      <origin rpy="0 1.57079 0" xyz="0 0 0"/>
    </collision>
  </link>
  <joint name="RHand" type="fixed">
    <parent link="r_wrist"/>
    <child link="r_gripper"/>
    <origin rpy="0 0 0" xyz="0.05775 0 -0.01213"/>
    <axis xyz="1.0 0 0"/>
    <limit effort="0.292" lower="0" upper="1.0" velocity="8.33"/>
  </joint>
  <link name="r_gripper">
    <inertial>
      <mass value="2e-06"/>
      <inertia ixx="1.1e-09" ixy="0" ixz="0" iyy="1.1e-09" iyz="0" izz="1.1e-09"/>
    </inertial>
  </link>
  <joint name="LHipYawPitch" type="revolute">
    <parent link="torso"/>
    <child link="LPelvis"/>
    <origin rpy="0 0 0" xyz="0 0.05 -0.085"/>
    <axis xyz="0 0.707106 -0.707106"/>
    <limit effort="3.348" lower="-1.14529" upper="0.740718" velocity="4.16174"/>
  </joint>
  <link name="LPelvis">
    <inertial>
      <mass value="0.06981"/>
      <inertia ixx="8.15e-05" ixy="-4.994e-06" ixz="1.275e-05" iyy="0.000101" iyz="2.345e-05" izz="6.262e-05"/>
      <origin rpy="0 0 0" xyz="-0.00781 -0.01114 0.02661"/>
    </inertial>
    <visual>
      <geometry>
        <mesh filename="../meshes/LHipYawPitch.dae" scale="0.1 0.1 0.1"/>
      </geometry>
      <origin rpy="0 0 0" xyz="0 0 0"/>
    </visual>
   <!--  <collision>
      <geometry>
        <mesh filename="../meshes/LHipYawPitch.obj" scale="0.1 0.1 0.1"/>
      </geometry>
      <origin rpy="0 0 0" xyz="0 0 0"/>
    </collision> -->
  </link>
  <joint name="LHipRoll" type="revolute">
    <parent link="LPelvis"/>
    <child link="LHip"/>
    <origin rpy="0 0 0" xyz="0 0 0"/>
    <axis xyz="1.0 0 0"/>
    <limit effort="3.348" lower="-0.379435" upper="0.79046" velocity="4.16174"/>
  </joint>
  <link name="LHip">
    <inertial>
      <mass value="0.14053"/>
      <inertia ixx="2.758e-05" ixy="-2.233e-08" ixz="-4.082e-06" iyy="9.827e-05" iyz="-4.19e-09" izz="8.81e-05"/>
      <origin rpy="0 0 0" xyz="-0.01549 0.00029 -0.00515"/>
    </inertial>
    <visual>
      <geometry>
        <mesh filename="../meshes/LHipRoll.dae" scale="0.1 0.1 0.1"/>
      </geometry>
      <origin rpy="0 0 0" xyz="0 0 0"/>
    </visual>
  </link>
  <joint name="LHipPitch" type="revolute">
    <parent link="LHip"/>
    <child link="LThigh"/>
    <origin rpy="0 0 0" xyz="0 0 0"/>
    <axis xyz="0 1.0 0"/>
    <limit effort="3.023" lower="-1.53589" upper="0.48398" velocity="6.40239"/>
  </joint>
  <link name="LThigh">
    <inertial>
      <mass value="0.38968"/>
      <inertia ixx="0.00164" ixy="9.245e-07" ixz="8.530e-05" iyy="0.00159" iyz="3.836e-05" izz="0.000304"/>
      <origin rpy="0 0 0" xyz="0.00138 0.00221 -0.05373"/>
    </inertial>
    <visual>
      <geometry>
        <mesh filename="../meshes/LHipPitch.dae" scale="0.1 0.1 0.1"/>
      </geometry>
      <origin rpy="0 0 0" xyz="0 0 0"/>
    </visual>
    <!-- <collision>
      <geometry>
        <mesh filename="../meshes/LHipPitch.obj" scale="0.1 0.1 0.08"/>
      </geometry>
      <origin rpy="0 0 0" xyz="0 0 0"/>
    </collision> -->
    <collision>
      <geometry>
        <cylinder length="0.04" radius="0.042"/>
      </geometry>
      <origin rpy="0 0 0" xyz="0. -0. -0.07"/>
    </collision>
  </link>
  <joint name="LKneePitch" type="revolute">
    <parent link="LThigh"/>
    <child link="LTibia"/>
    <origin rpy="0 0 0" xyz="0 0 -0.1"/>
    <axis xyz="0 1.0 0"/>
    <limit effort="3.023" lower="-0.0923279" upper="2.11255" velocity="6.40239"/>
  </joint>
  <link name="LTibia">
    <inertial>
      <mass value="0.30142"/>
      <inertia ixx="0.00118" ixy="6.336e-06" ixz="3.6497e-05" iyy="0.00113" iyz="3.9495e-05" izz="0.000193"/>
      <origin rpy="0 0 0" xyz="0.00453 0.00225 -0.04936"/>
    </inertial>
    <visual>
      <geometry>
        <mesh filename="../meshes/LKneePitch.dae" scale="0.1 0.1 0.1"/>
      </geometry>
      <origin rpy="0 0 0" xyz="0 0 0"/>
    </visual>
    <!-- <collision>
      <geometry>
        <mesh filename="../meshes/LKneePitch.obj" scale="0.1 0.1 0.08"/>
      </geometry>
      <origin rpy="0 0 0" xyz="0 0 0"/>
    </collision> -->
  </link>
  <joint name="LAnklePitch" type="revolute">
    <parent link="LTibia"/>
    <child link="LAnklePitch"/>
    <origin rpy="0 0 0" xyz="0 0 -0.1029"/>
    <axis xyz="0 1.0 0"/>
    <limit effort="3.023" lower="-1.18944" upper="0.922581" velocity="6.40239"/>
  </joint>
  <link name="LAnklePitch">
    <inertial>
      <mass value="0.13416"/>
      <inertia ixx="3.851e-05" ixy="-2.634e-08" ixz="3.862e-06" iyy="7.4265e-05" iyz="1.834e-08" izz="5.4865e-05"/>
      <origin rpy="0 0 0" xyz="0.00045 0.00029 0.00685"/>
    </inertial>
    <visual>
      <geometry>
        <mesh filename="../meshes/LAnklePitch.dae" scale="0.1 0.1 0.1"/>
      </geometry>
      <origin rpy="0 0 0" xyz="0 0 0"/>
    </visual>
    <!-- <collision>
      <geometry>
        <mesh filename="../meshes/LAnklePitch.obj" scale="0.1 0.1 0.1"/>
      </geometry>
      <origin rpy="0 0 0" xyz="0 0 0"/>
    </collision> -->
  </link>
  <joint name="LAnkleRoll" type="revolute">
    <parent link="LAnklePitch"/>
    <child link="l_ankle"/>
    <origin rpy="0 0 0" xyz="0 0 0"/>
    <axis xyz="1.0 0 0"/>
    <limit effort="3.348" lower="-0.397761" upper="0.768992" velocity="4.16174"/>
  </joint>
  <link name="l_ankle">
    <inertial>
      <mass value="0.17184"/>
      <inertia ixx="0.000269" ixy="-5.696e-06" ixz="0.000139" iyy="0.000644" iyz="1.874e-05" izz="0.000526"/>
      <origin rpy="0 0 0" xyz="0.02542 0.0033 -0.03239"/>
    </inertial>
    <visual>
      <geometry>
        <mesh filename="../meshes/LAnkleRoll.dae" scale="0.1 0.1 0.1"/>
      </geometry>
      <origin rpy="0 0 0" xyz="0 0 0"/>
    </visual>
    <!-- <collision>
      <geometry>
        <mesh filename="../meshes/LAnkleRoll.obj" scale="0.1 0.08 0.1"/>
      </geometry>
      <origin rpy="0 0 0" xyz="0 0 0"/>
    </collision> -->
    <collision>
      <geometry>
        <box size="0.14 0.09 0.04"/>
      </geometry>
      <origin rpy="0 0 0" xyz="0.023 0.009 -0.016"/>
    </collision>
  </link>
  <joint name="LLeg_effector_fixedjoint" type="fixed" dont_collapse="true">
    <parent link="l_ankle"/>
    <child link="l_sole"/>
    <origin rpy="0 0 0" xyz="0 0 -0.04511"/>
    <axis xyz="0 0 0"/>
  </joint>
  <link name="l_sole">
    <inertial>
      <mass value="0.01"/>
      <inertia ixx="0" ixy="0" ixz="0" iyy="0" iyz="0" izz="0"/>
    </inertial>
    <!-- <collision>
      <geometry>
        <cylinder length="0.10" radius="0.004"/>
      </geometry>
      <origin rpy="0 1.57079 0" xyz="0.023 0.048 0.003"/>
    </collision>
    <collision>
      <geometry>
        <cylinder length="0.10" radius="0.004"/>
      </geometry>
      <origin rpy="0 1.57079 0" xyz="0.023 -0.03 0.003"/>
    </collision>
    <collision>
      <geometry>
        <cylinder length="0.025" radius="0.004"/>
      </geometry>
      <origin rpy="0 1.57079 1.57079" xyz="0.095 0.009 0.003"/>
    </collision>
    <collision>
      <geometry>
        <cylinder length="0.078" radius="0.004"/>
      </geometry>
      <origin rpy="0 1.57079 1.57079" xyz="-0.037 0.009 0.003"/>
    </collision> -->
        <collision>
      <geometry>
        <sphere radius="0.006"/>
      </geometry>
      <origin rpy="0 0 0" xyz="-0.037 0.048 0.005"/>
    </collision>
    <collision>
      <geometry>
        <sphere radius="0.006"/>
      </geometry>
      <origin rpy="0 0 0" xyz="-0.037 -0.03 0.005"/>
    </collision>
    <collision>
      <geometry>
        <sphere radius="0.006"/>
      </geometry>
      <origin rpy="0 0 0" xyz="0.095 0.048 0.005"/>
    </collision>
    <collision>
      <geometry>
        <sphere radius="0.006"/>
      </geometry>
      <origin rpy="0 0 0" xyz="0.095 -0.03 0.005"/>
    </collision>
  </link>
  <joint name="RHipYawPitch" type="revolute">
    <parent link="torso"/>
    <child link="RPelvis"/>
    <origin rpy="0 0 0" xyz="0 -0.05 -0.085"/>
    <axis xyz="0 0.707106 0.707106"/>
    <limit effort="3.348" lower="-1.14529" upper="0.740718" velocity="4.16174"/>
    <mimic joint="LHipYawPitch" multiplier="1.0" offset="0"/>
  </joint>
  <link name="RPelvis">
    <inertial>
      <mass value="0.06981"/>
      <inertia ixx="8.997e-05" ixy="5.002e-06" ixz="1.274e-05" iyy="0.0001055" iyz="-2.77e-05" izz="6.689e-05"/>
      <origin rpy="0 0 0" xyz="-0.00781 0.01114 0.02661"/>
    </inertial>
    <visual>
      <geometry>
        <mesh filename="../meshes/RHipYawPitch.dae" scale="0.1 0.1 0.1"/>
      </geometry>
      <origin rpy="0 0 0" xyz="0 0 0"/>
    </visual>
    <!-- <collision>
      <geometry>
        <mesh filename="../meshes/RHipYawPitch.obj" scale="0.1 0.1 0.1"/>
      </geometry>
      <origin rpy="0 0 0" xyz="0 0 0"/>
    </collision> -->
  </link>
  <joint name="RHipRoll" type="revolute">
    <parent link="RPelvis"/>
    <child link="RHip"/>
    <origin rpy="0 0 0" xyz="0 0 0"/>
    <axis xyz="1.0 0 0"/>
    <limit effort="3.348" lower="-0.79046" upper="0.379435" velocity="4.16174"/>
  </joint>
  <link name="RHip">
    <inertial>
      <mass value="0.14053"/>
      <inertia ixx="2.759e-05" ixy="-1.919e-08" ixz="-4.108e-06" iyy="9.827e-05" iyz="2.51e-09" izz="8.81e-05"/>
      <origin rpy="0 0 0" xyz="-0.01549 -0.00029 -0.00515"/>
    </inertial>
    <visual>
      <geometry>
        <mesh filename="../meshes/RHipRoll.dae" scale="0.1 0.1 0.1"/>
      </geometry>
      <origin rpy="0 0 0" xyz="0 0 0"/>
    </visual>
  </link>
  <joint name="RHipPitch" type="revolute">
    <parent link="RHip"/>
    <child link="RThigh"/>
    <origin rpy="0 0 0" xyz="0 0 0"/>
    <axis xyz="0 1.0 0"/>
    <limit effort="3.0226" lower="-1.53589" upper="0.48398" velocity="6.40239"/>
  </joint>
  <link name="RThigh">
    <inertial>
      <mass value="0.38968"/>
      <inertia ixx="0.00164" ixy="-8.395e-07" ixz="8.588e-05" iyy="0.00152" iyz="-3.918e-05" izz="0.000304"/>
      <origin rpy="0 0 0" xyz="0.00138 -0.00221 -0.05373"/>
    </inertial>
    <visual>
      <geometry>
        <mesh filename="../meshes/RHipPitch.dae" scale="0.1 0.1 0.1"/>
      </geometry>
      <origin rpy="0 0 0" xyz="0 0 0"/>
    </visual>
    <!-- <collision>
      <geometry>
        <mesh filename="../meshes/RHipPitch.obj" scale="0.1 0.1 0.08"/>
      </geometry>
      <origin rpy="0 0 0" xyz="0 0 0"/>
    </collision> -->
    <collision>
      <geometry>
        <cylinder length="0.04" radius="0.042"/>
      </geometry>
      <origin rpy="0 0 0" xyz="0. -0. -0.07"/>
    </collision>
  </link>
  <joint name="RKneePitch" type="revolute">
    <parent link="RThigh"/>
    <child link="RTibia"/>
    <origin rpy="0 0 0" xyz="0 0 -0.1"/>
    <axis xyz="0 1.0 0"/>
    <limit effort="3.0226" lower="-0.0923279" upper="2.11255" velocity="6.40239"/>
  </joint>
  <link name="RTibia">
    <inertial>
      <mass value="0.30142"/>
      <inertia ixx="0.00118" ixy="-8.965e-07" ixz="2.7997e-05" iyy="0.00113" iyz="-3.848e-05" izz="0.000191"/>
      <origin rpy="0 0 0" xyz="0.00453 -0.00225 -0.04936"/>
    </inertial>
    <visual>
      <geometry>
        <mesh filename="../meshes/RKneePitch.dae" scale="0.1 0.1 0.1"/>
      </geometry>
      <origin rpy="0 0 0" xyz="0 0 0"/>
    </visual>
    <!-- <collision>
      <geometry>
        <mesh filename="../meshes/RKneePitch.obj" scale="0.1 0.1 0.08"/>
      </geometry>
      <origin rpy="0 0 0" xyz="0 0 0"/>
    </collision> -->
  </link>
  <joint name="RAnklePitch" type="revolute">
    <parent link="RTibia"/>
    <child link="RAnklePitch"/>
    <origin rpy="0 0 0" xyz="0 0 -0.1029"/>
    <axis xyz="0 1.0 0"/>
    <limit effort="3.0226" lower="-1.1863" upper="0.932006" velocity="6.40239"/>
  </joint>
  <link name="RAnklePitch">
    <inertial>
      <mass value="0.13416"/>
      <inertia ixx="3.851e-05" ixy="6.434e-08" ixz="3.875e-06" iyy="7.431e-05" iyz="-4.58e-09" izz="5.491e-05"/>
      <origin rpy="0 0 0" xyz="0.00045 -0.00029 0.00685"/>
    </inertial>
    <visual>
      <geometry>
        <mesh filename="../meshes/RAnklePitch.dae" scale="0.1 0.1 0.1"/>
      </geometry>
      <origin rpy="0 0 0" xyz="0 0 0"/>
    </visual>
    <!-- <collision>
      <geometry>
        <mesh filename="../meshes/RAnklePitch.obj" scale="0.1 0.1 0.1"/>
      </geometry>
      <origin rpy="0 0 0" xyz="0 0 0"/>
    </collision> -->
  </link>
  <joint name="RAnkleRoll" type="revolute">
    <parent link="RAnklePitch"/>
    <child link="r_ankle"/>
    <origin rpy="0 0 0" xyz="0 0 0"/>
    <axis xyz="1.0 0 0"/>
    <limit effort="3.348" lower="-0.768992" upper="0.397761" velocity="4.16174"/>
  </joint>
  <link name="r_ankle">
    <inertial>
      <mass value="0.17184"/>
      <inertia ixx="0.000269" ixy="5.875e-06" ixz="0.000139" iyy="0.000643" iyz="-1.885e-05" izz="0.000525"/>
      <origin rpy="0 0 0" xyz="0.02542 -0.0033 -0.03239"/>
    </inertial>
    <visual>
      <geometry>
        <mesh filename="../meshes/RAnkleRoll.dae" scale="0.1 0.1 0.1"/>
      </geometry>
      <origin rpy="0 0 0" xyz="0 0 0"/>
    </visual>
    <!-- <collision>
      <geometry>
        <mesh filename="../meshes/RAnkleRoll.obj" scale="0.1 0.08 0.1"/>
      </geometry>
      <origin rpy="0 0 0" xyz="0 0 0"/>
    </collision> -->
    <collision>
      <geometry>
        <box size="0.14 0.09 0.042"/>
      </geometry>
      <origin rpy="0 0 0" xyz="0.023 -0.009 -0.016"/>
    </collision>
  </link>
  <joint name="RLeg_effector_fixedjoint" type="fixed" dont_collapse="true">
    <parent link="r_ankle"/>
    <child link="r_sole"/>
    <origin rpy="0 0 0" xyz="0 0 -0.04511"/>
    <axis xyz="0 0 0"/>
  </joint>
  <link name="r_sole">
    <inertial>
      <mass value="0.01"/>
      <inertia ixx="0" ixy="0" ixz="0" iyy="0" iyz="0" izz="0"/>
    </inertial>
    <!-- <collision>
      <geometry>
        <cylinder length="0.10" radius="0.004"/>
      </geometry>
      <origin rpy="0 1.57079 0" xyz="0.023 -0.048 0.003"/>
    </collision>
    <collision>
      <geometry>
        <cylinder length="0.10" radius="0.004"/>
      </geometry>
      <origin rpy="0 1.57079 0" xyz="0.023 0.03 0.003"/>
    </collision>
    <collision>
      <geometry>
        <cylinder length="0.025" radius="0.004"/>
      </geometry>
      <origin rpy="0 1.57079 1.57079" xyz="0.095 -0.009 0.003"/>
    </collision>
    <collision>
      <geometry>
        <cylinder length="0.078" radius="0.004"/>
      </geometry>
      <origin rpy="0 1.57079 1.57079" xyz="-0.037 -0.009 0.003"/>
    </collision> -->
    <collision>
      <geometry>
        <sphere radius="0.006"/>
      </geometry>
      <origin rpy="0 0 0" xyz="-0.037 -0.048 0.005"/>
    </collision>
    <collision>
      <geometry>
        <sphere radius="0.006"/>
      </geometry>
      <origin rpy="0 0 0" xyz="-0.037 0.03 0.005"/>
    </collision>
    <collision>
      <geometry>
        <sphere radius="0.006"/>
      </geometry>
      <origin rpy="0 0 0" xyz="0.095 -0.048 0.005"/>
    </collision>
    <collision>
      <geometry>
        <sphere radius="0.006"/>
      </geometry>
      <origin rpy="0 0 0" xyz="0.095 0.03 0.005"/>
    </collision>
  </link>

  <link name="LFootBumperRight_frame"/>
  <joint name="LFoot/Bumper/Right_sensor_fixedjoint" type="fixed">
    <parent link="l_ankle"/>
    <child link="LFootBumperRight_frame"/>
    <origin rpy="0 0 0" xyz="0.0876 -0.014 -0.0353"/>
    <axis xyz="0 0 0"/>
  </joint>
  <link name="RFsrRL_frame">
    <!-- <collision>
      <geometry>
        <box size="0.01 0.01 0.005"/>
      </geometry>
      <origin rpy="0 0 0" xyz="0 0 0"/>
    </collision> -->
    <inertial>
      <mass value="2e-06"/>
      <inertia ixx="1.1e-09" ixy="0" ixz="0" iyy="1.1e-09" iyz="0" izz="1.1e-09"/>
    </inertial>
  </link>
  <joint name="RFoot/FSR/RearLeft_sensor_fixedjoint" type="fixed">
    <parent link="r_ankle"/>
    <child link="RFsrRL_frame"/>
    <origin rpy="0 0 0" xyz="-0.03025 0.0191 -0.04511"/>
    <axis xyz="0 0 0"/>
  </joint>
  <link name="CameraBottom_optical_frame"/>
  <joint name="CameraBottom_optical_frame_fixedjoint" type="fixed">
    <parent link="CameraBottom_frame"/>
    <child link="CameraBottom_optical_frame"/>
    <origin rpy="-1.57079632679 0 -1.57079632679" xyz="0 0 0"/>
  </joint>
  <link name="RFsrRR_frame">
    <!-- <collision>
      <geometry>
        <box size="0.01 0.01 0.005"/>
      </geometry>
      <origin rpy="0 0 0" xyz="0 0 0"/>
    </collision> -->
    <inertial>
      <mass value="2e-06"/>
      <inertia ixx="1.1e-09" ixy="0" ixz="0" iyy="1.1e-09" iyz="0" izz="1.1e-09"/>
    </inertial>
  </link>
  <joint name="RFoot/FSR/RearRight_sensor_fixedjoint" type="fixed">
    <parent link="r_ankle"/>
    <child link="RFsrRR_frame"/>
    <origin rpy="0 0 0" xyz="-0.02965 -0.0299 -0.04511"/>
    <axis xyz="0 0 0"/>
  </joint>
  <link name="LFsrFR_frame">
    <!-- <collision>
      <geometry>
        <box size="0.01 0.01 0.005"/>
      </geometry>
      <origin rpy="0 0 0" xyz="0 0 0"/>
    </collision> -->
    <inertial>
      <mass value="2e-06"/>
      <inertia ixx="1.1e-09" ixy="0" ixz="0" iyy="1.1e-09" iyz="0" izz="1.1e-09"/>
    </inertial>
  </link>
  <joint name="LFoot/FSR/FrontRight_sensor_fixedjoint" type="fixed">
    <parent link="l_ankle"/>
    <child link="LFsrFR_frame"/>
    <origin rpy="0 0 0" xyz="0.07025 -0.0231 -0.04511"/>
    <axis xyz="0 0 0"/>
  </joint>
  <link name="LHandTouchLeft_frame"/>
  <joint name="LHand/Touch/Left_sensor_fixedjoint" type="fixed">
    <parent link="l_wrist"/>
    <child link="LHandTouchLeft_frame"/>
    <origin rpy="0 0 1.5708" xyz="0.032 0.025 0.003"/>
    <axis xyz="0 0 0"/>
  </joint>
  <link name="RFootBumperRight_frame"/>
  <joint name="RFoot/Bumper/Right_sensor_fixedjoint" type="fixed">
    <parent link="r_ankle"/>
    <child link="RFootBumperRight_frame"/>
    <origin rpy="0 0 0" xyz="0.0876 -0.019 -0.0353"/>
    <axis xyz="0 0 0"/>
  </joint>
  <link name="RFsrFR_frame">
    <!-- <collision>
      <geometry>
        <box size="0.01 0.01 0.005"/>
      </geometry>
      <origin rpy="0 0 0" xyz="0 0 0"/>
    </collision> -->
    <inertial>
      <mass value="2e-06"/>
      <inertia ixx="1.1e-09" ixy="0" ixz="0" iyy="1.1e-09" iyz="0" izz="1.1e-09"/>
    </inertial>
  </link>
  <joint name="RFoot/FSR/FrontRight_sensor_fixedjoint" type="fixed">
    <parent link="r_ankle"/>
    <child link="RFsrFR_frame"/>
    <origin rpy="0 0 0" xyz="0.07025 -0.0299 -0.04511"/>
    <axis xyz="0 0 0"/>
  </joint>
  <link name="LFsrRR_frame">
    <!-- <collision>
      <geometry>
        <box size="0.01 0.01 0.005"/>
      </geometry>
      <origin rpy="0 0 0" xyz="0 0 0"/>
    </collision> -->
    <inertial>
      <mass value="2e-06"/>
      <inertia ixx="1.1e-09" ixy="0" ixz="0" iyy="1.1e-09" iyz="0" izz="1.1e-09"/>
    </inertial>
  </link>
  <joint name="LFoot/FSR/RearRight_sensor_fixedjoint" type="fixed">
    <parent link="l_ankle"/>
    <child link="LFsrRR_frame"/>
    <origin rpy="0 0 0" xyz="-0.02965 -0.0191 -0.04511"/>
    <axis xyz="0 0 0"/>
  </joint>
  <link name="ImuTorsoAccelerometer_frame"/>
  <joint name="Accelerometer_sensor_fixedjoint" type="fixed" dont_collapse="false">
    <parent link="torso"/>
    <child link="ImuTorsoAccelerometer_frame"/>
    <origin rpy="0 0 0" xyz="-0.008 0.00606 0.027"/>
    <axis xyz="0 0 0"/>
  </joint>
  <link name="HeadTouchFront_frame"/>
  <joint name="Head/Touch/Front_sensor_fixedjoint" type="fixed">
    <parent link="Head"/>
    <child link="HeadTouchFront_frame"/>
    <origin rpy="0 -1.1861 0" xyz="0.0312 0 0.1014"/>
    <axis xyz="0 0 0"/>
  </joint>
  <link name="RFootBumperLeft_frame"/>
  <joint name="RFoot/Bumper/Left_sensor_fixedjoint" type="fixed">
    <parent link="r_ankle"/>
    <child link="RFootBumperLeft_frame"/>
    <origin rpy="0 0 0" xyz="0.0876 0.014 -0.0353"/>
    <axis xyz="0 0 0"/>
  </joint>
  <link name="RSonar_frame"/>
  <joint name="Sonar/Right_sensor_fixedjoint" type="fixed">
    <parent link="torso"/>
    <child link="RSonar_frame"/>
    <origin rpy="0.00478508 0.0436497 -0.392441" xyz="0.00558253 -0.0192068 0.0623853"/>
    <axis xyz="0 0 0"/>
  </joint>
  <link name="RHandTouchRight_frame"/>
  <joint name="RHand/Touch/Right_sensor_fixedjoint" type="fixed">
    <parent link="r_wrist"/>
    <child link="RHandTouchRight_frame"/>
    <origin rpy="0 0 -1.5708" xyz="0.035 -0.025 0.0035"/>
    <axis xyz="0 0 0"/>
  </joint>
  <link name="RHandTouchBack_frame"/>
  <joint name="RHand/Touch/Back_sensor_fixedjoint" type="fixed">
    <parent link="r_wrist"/>
    <child link="RHandTouchBack_frame"/>
    <origin rpy="3.14159 -1.5708 3.14159" xyz="0.038 0 0.025"/>
    <axis xyz="0 0 0"/>
  </joint>
  <link name="RFsrFL_frame">
    <!-- <collision>
      <geometry>
        <box size="0.01 0.01 0.005"/>
      </geometry>
      <origin rpy="0 0 0" xyz="0 0 0"/>
    </collision> -->
    <inertial>
      <mass value="2e-06"/>
      <inertia ixx="1.1e-09" ixy="0" ixz="0" iyy="1.1e-09" iyz="0" izz="1.1e-09"/>
    </inertial>
  </link>
  <joint name="RFoot/FSR/FrontLeft_sensor_fixedjoint" type="fixed">
    <parent link="r_ankle"/>
    <child link="RFsrFL_frame"/>
    <origin rpy="0 0 0" xyz="0.07025 0.0231 -0.04511"/>
    <axis xyz="0 0 0"/>
  </joint>
  <link name="LSonar_frame"/>
  <joint name="Sonar/Left_sensor_fixedjoint" type="fixed">
    <parent link="torso"/>
    <child link="LSonar_frame"/>
    <origin rpy="-0.00478508 0.0436497 0.392441" xyz="0.00558253 0.0192068 0.0623853"/>
    <axis xyz="0 0 0"/>
  </joint>
  <link name="LFsrFL_frame">
    <!-- <collision>
      <geometry>
        <box size="0.01 0.01 0.005"/>
      </geometry>
      <origin rpy="0 0 0" xyz="0 0 0"/>
    </collision> -->
    <inertial>
      <mass value="2e-06"/>
      <inertia ixx="1.1e-09" ixy="0" ixz="0" iyy="1.1e-09" iyz="0" izz="1.1e-09"/>
    </inertial>
  </link>
  <joint name="LFoot/FSR/FrontLeft_sensor_fixedjoint" type="fixed">
    <parent link="l_ankle"/>
    <child link="LFsrFL_frame"/>
    <origin rpy="0 0 0" xyz="0.07025 0.0299 -0.04511"/>
    <axis xyz="0 0 0"/>
  </joint>
  <link name="LFsrRL_frame">
    <!-- <collision>
      <geometry>
        <box size="0.01 0.01 0.005"/>
      </geometry>
      <origin rpy="0 0 0" xyz="0 0 0"/>
    </collision> -->
    <inertial>
      <mass value="2e-06"/>
      <inertia ixx="1.1e-09" ixy="0" ixz="0" iyy="1.1e-09" iyz="0" izz="1.1e-09"/>
    </inertial>
  </link>
  <joint name="LFoot/FSR/RearLeft_sensor_fixedjoint" type="fixed">
    <parent link="l_ankle"/>
    <child link="LFsrRL_frame"/>
    <origin rpy="0 0 0" xyz="-0.03025 0.0299 -0.04511"/>
    <axis xyz="0 0 0"/>
  </joint>
  <link name="RHandTouchLeft_frame"/>
  <joint name="RHand/Touch/Left_sensor_fixedjoint" type="fixed">
    <parent link="r_wrist"/>
    <child link="RHandTouchLeft_frame"/>
    <origin rpy="0 0 1.5708" xyz="0.032 0.025 0.003"/>
    <axis xyz="0 0 0"/>
  </joint>
  <link name="CameraBottom_frame"/>
  <joint name="CameraBottom_sensor_fixedjoint" type="fixed">
    <parent link="Head"/>
    <child link="CameraBottom_frame"/>
    <origin rpy="0 0.692896 0" xyz="0.05071 0 0.01774"/>
    <axis xyz="0 0 0"/>
  </joint>
  <link name="CameraTop_frame"/>
  <joint name="CameraTop_sensor_fixedjoint" type="fixed">
    <parent link="Head"/>
    <child link="CameraTop_frame"/>
    <origin rpy="0 0.0209435 0" xyz="0.05871 0 0.06364"/>
    <axis xyz="0 0 0"/>
  </joint>
  <link name="CameraTop_optical_frame"/>
  <joint name="CameraTop_optical_frame_fixedjoint" type="fixed">
    <parent link="CameraTop_frame"/>
    <child link="CameraTop_optical_frame"/>
    <origin rpy="-1.57079632679 0 -1.57079632679" xyz="0 0 0"/>
  </joint>
  <link name="LHandTouchBack_frame"/>
  <joint name="LHand/Touch/Back_sensor_fixedjoint" type="fixed">
    <parent link="l_wrist"/>
    <child link="LHandTouchBack_frame"/>
    <origin rpy="3.14159 -1.5708 3.14159" xyz="0.038 0 0.025"/>
    <axis xyz="0 0 0"/>
  </joint>
  <link name="LInfraRed_frame"/>
  <joint name="InfraredL_sensor_fixedjoint" type="fixed">
    <parent link="Head"/>
    <child link="LInfraRed_frame"/>
    <origin rpy="0 0 0" xyz="0.0441 0.0257 0.0466"/>
    <axis xyz="0 0 0"/>
  </joint>
  <link name="ImuTorsoGyrometer_frame"/>
  <joint name="Gyrometer_sensor_fixedjoint" type="fixed">
    <parent link="torso"/>
    <child link="ImuTorsoGyrometer_frame"/>
    <origin rpy="0 0 0" xyz="-0.008 0.006 0.029"/>
    <axis xyz="0 0 0"/>
  </joint>
  <link name="HeadTouchRear_frame"/>
  <joint name="Head/Touch/Rear_sensor_fixedjoint" type="fixed">
    <parent link="Head"/>
    <child link="HeadTouchRear_frame"/>
    <origin rpy="3.14159 -1.33319 -3.14159" xyz="-0.0257 0 0.1045"/>
    <axis xyz="0 0 0"/>
  </joint>
  <link name="HeadTouchMiddle_frame"/>
  <joint name="Head/Touch/Middle_sensor_fixedjoint" type="fixed">
    <parent link="Head"/>
    <child link="HeadTouchMiddle_frame"/>
    <origin rpy="3.14159 -1.57079 -3.14159" xyz="0.001 0 0.1099"/>
    <axis xyz="0 0 0"/>
  </joint>
  <link name="RInfraRed_frame"/>
  <joint name="InfraredR_sensor_fixedjoint" type="fixed">
    <parent link="Head"/>
    <child link="RInfraRed_frame"/>
    <origin rpy="0 0 0" xyz="0.0441 -0.0257 0.0466"/>
    <axis xyz="0 0 0"/>
  </joint>
  <link name="ChestButton_frame"/>
  <joint name="ChestBoard/Button_sensor_fixedjoint" type="fixed">
    <parent link="torso"/>
    <child link="ChestButton_frame"/>
    <origin rpy="0 0 0" xyz="0.049871 0.001588 0.055163"/>
    <axis xyz="0 0 0"/>
  </joint>
  <link name="LFootBumperLeft_frame"/>
  <joint name="LFoot/Bumper/Left_sensor_fixedjoint" type="fixed">
    <parent link="l_ankle"/>
    <child link="LFootBumperLeft_frame"/>
    <origin rpy="0 0 0" xyz="0.0876 0.019 -0.0353"/>
    <axis xyz="0 0 0"/>
  </joint>
  <link name="LHandTouchRight_frame"/>
  <joint name="LHand/Touch/Right_sensor_fixedjoint" type="fixed">
    <parent link="l_wrist"/>
    <child link="LHandTouchRight_frame"/>
    <origin rpy="0 0 -1.5708" xyz="0.035 -0.025 0.0035"/>
    <axis xyz="0 0 0"/>
  </joint>
</robot>
